<?xml version="1.0" encoding="utf-8"?>
<robot xmlns:xacro="http://www.ros.org/wiki/xacro" name="four_wheel_urdf">
<!-- This URDF was automatically created by SolidWorks to URDF Exporter! Originally created by Stephen Brawner (brawner@gmail.com) 
     Commit Version: 1.5.1-0-g916b5db  Build Version: 1.5.7152.31018
     For more information, please see http://wiki.ros.org/sw_urdf_exporter -->
<!--Model constructed by yu zhuotong 2020.5.10-->

<!--mass property-->
  <xacro:property name = "wheel_mass" value = "0.5"/>
  <xacro:property name = "lidar_mass" value = "2"/>
  <xacro:property name = "kinect_mass" value = "0.5"/>

<!--simplified wheel collision model-->
  <xacro:macro name = "wheel_shape">
    <cylinder radius="${0.10/2}" length="0.06"/>
  </xacro:macro>

<!--add physical properties and transmissions for wheels-->
  <xacro:macro name = "wheel_property" params="prefix suffix">
  <!--physical properties for gazebo simulator-->
    <gazebo reference="${prefix}_${suffix}_wheel">
      <mu1 value="200.0"/>
      <mu2 value="100.0"/>
      <kp value="10000000.0" />
      <kd value="1.0" />
      <material>Gazebo/Grey</material>
    </gazebo>

  <!--transmissions-->
    <transmission name="${prefix}_${suffix}_wheel_trans">
      <type>transmission_interface/SimpleTransmission</type>
      <actuator name="${prefix}_${suffix}_motor">
        <mechanicalReduction>1</mechanicalReduction>
      </actuator>
      <joint name="${prefix}_${suffix}_joint">
        <hardwareInterface>VelocityJointInterface</hardwareInterface>
      </joint>
    </transmission>
  </xacro:macro>




  <!--the main part begins here -->
  <link
    name="base_link">
    <inertial>
      <origin
        xyz="-0.0644848464679869 0.00231849207323701 0.150032010142397"
        rpy="0 0 0" />
      <mass
        value="2.37412974413616" />
      <inertia
        ixx="0.0108285754206111"
        ixy="4.37384081704876E-06"
        ixz="3.3848939661042E-19"
        iyy="0.0112553750782484"
        iyz="-1.27217147689861E-18"
        izz="0.0209821885086629" />
    </inertial>
    <visual>
      <origin
        xyz="0 0 0"
        rpy="0 0 0" />
      <geometry>
        <mesh
          filename="package://four_wheel_urdf/meshes/base_link.STL" />
      </geometry>
      <material
        name="">
        <color
          rgba="1 1 1 1" />
      </material>
    </visual>
    <collision>
      <origin
        xyz="0 0 0"
        rpy="0 0 0" />
      <geometry>
        <mesh
          filename="package://four_wheel_urdf/meshes/base_link.STL" />
      </geometry>
    </collision>
  </link>
  <link
    name="front_left_wheel">
    <inertial>
      <origin
        xyz="2.59347901092333E-07 -1.06081553569171E-07 -0.0173966059410684"
        rpy="0 0 0" />
      <mass
        value="${wheel_mass}" />
      <!--
      <mass
        value="0.186539970489831" />
      -->
      <inertia
        ixx="0.000153302092922362"
        ixy="3.15690566204019E-11"
        ixz="-8.74689995592684E-10"
        iyy="0.000153302050961775"
        iyz="-1.00904632576071E-10"
        izz="0.000279378682392963" />
    </inertial>
    <visual>
      <origin
        xyz="0 0 0"
        rpy="0 0 0" />
      <geometry>
        <mesh
          filename="package://four_wheel_urdf/meshes/front_left_wheel.STL" />
      </geometry>
      <material
        name="">
        <color
          rgba="0.8 0.803921568627451 0.8 1" />
      </material>
    </visual>
    <collision>
      <origin
        xyz="0 0 0"
        rpy="0 0 0" />
      <geometry>
      <xacro:wheel_shape/>
       <!--
        <mesh
          filename="package://four_wheel_urdf/meshes/front_left_wheel.STL" />
          -->
      </geometry>
    </collision>
  </link>
  <joint
    name="front_left_joint"
    type="continuous">
    <origin
      xyz="0.137625631329235 0.15756248166201 -0.0123743686707646"
      rpy="1.5707963267949 -1.09222488301814 0" />
    <parent
      link="base_link" />
    <child
      link="front_left_wheel" />
    <axis
      xyz="0 0 1" />
  </joint>
  <link
    name="front_right_wheel">
    <inertial>
      <origin
        xyz="2.59349533234671E-07 -1.05805539746262E-07 0.0173971507290964"
        rpy="0 0 0" />
      <mass
        value="${wheel_mass}" />
      <inertia
        ixx="0.000153302490492137"
        ixy="-1.30045833866925E-10"
        ixz="-7.39875321573544E-10"
        iyy="0.000153302370766279"
        iyz="6.64727474895905E-11"
        izz="0.000279379139317629" />
    </inertial>
    <visual>
      <origin
        xyz="0 0 0"
        rpy="0 0 0" />
      <geometry>
        <mesh
          filename="package://four_wheel_urdf/meshes/front_right_wheel.STL" />
      </geometry>
      <material
        name="">
        <color
          rgba="0.8 0.803921568627451 0.8 1" />
      </material>
    </visual>
    <collision>
      <origin
        xyz="0 0 0"
        rpy="0 0 0" />
      <geometry>
        <xacro:wheel_shape/>
       <!--
        <mesh
          filename="package://four_wheel_urdf/meshes/front_right_wheel.STL" />
          -->
      </geometry>
    </collision>
  </link>
  <joint
    name="front_right_joint"
    type="continuous">
    <origin
      xyz="0.137625631329235 -0.15756248166201 -0.0123743686707646"
      rpy="-1.57079632679489 -1.54165987688924 3.14159265358979" />
    <parent
      link="base_link" />
    <child
      link="front_right_wheel" />
    <axis
      xyz="0 0 1" />
  </joint>
  <link
    name="back_left_wheel">
    <inertial>
      <origin
        xyz="2.59254475457049E-07 -1.06128204363509E-07 -0.0173966059322994"
        rpy="0 0 0" />
      <mass
        value="${wheel_mass}" />
      <inertia
        ixx="0.000153302490497661"
        ixy="-1.29825169759262E-10"
        ixz="-7.40101026565892E-10"
        iyy="0.000153302370516275"
        iyz="6.63362847847309E-11"
        izz="0.000279379139155462" />
    </inertial>
    <visual>
      <origin
        xyz="0 0 0"
        rpy="0 0 0" />
      <geometry>
        <mesh
          filename="package://four_wheel_urdf/meshes/back_left_wheel.STL" />
      </geometry>
      <material
        name="">
        <color
          rgba="0.8 0.803921568627451 0.8 1" />
      </material>
    </visual>
    <collision>
      <origin
        xyz="0 0 0"
        rpy="0 0 0" />
      <geometry>
      <xacro:wheel_shape/>
       <!--
        <mesh
          filename="package://four_wheel_urdf/meshes/back_left_wheel.STL" />
          -->
      </geometry>
    </collision>
  </link>
  <joint
    name="back_left_joint"
    type="continuous">
    <origin
      xyz="-0.137625631329235 0.15756248166201 -0.0123743686707646"
      rpy="1.5707963267949 0.972888437481976 0" />
    <parent
      link="base_link" />
    <child
      link="back_left_wheel" />
    <axis
      xyz="0 0 1" />
  </joint>
  <link
    name="back_right_wheel">
    <inertial>
      <origin
        xyz="2.59034111976114E-07 -1.05729380417419E-07 0.0173971507538941"
        rpy="0 0 0" />
      <mass
        value="${wheel_mass}" />
      <inertia
        ixx="0.000153302490504048"
        ixy="-1.30083259252405E-10"
        ixz="-7.39891084911436E-10"
        iyy="0.000153302370276612"
        iyz="6.62814445890268E-11"
        izz="0.000279379138856014" />
    </inertial>
    <visual>
      <origin
        xyz="0 0 0"
        rpy="0 0 0" />
      <geometry>
        <mesh
          filename="package://four_wheel_urdf/meshes/back_right_wheel.STL" />
      </geometry>
      <material
        name="">
        <color
          rgba="0.8 0.803921568627451 0.8 1" />
      </material>
    </visual>
    <collision>
      <origin
        xyz="0 0 0"
        rpy="0 0 0" />
      <geometry>
      <xacro:wheel_shape/>
       <!--
        <mesh
          filename="package://four_wheel_urdf/meshes/back_right_wheel.STL" />
          -->
      </geometry>
    </collision>
  </link>
  <joint
    name="back_right_joint"
    type="continuous">
    <origin
      xyz="-0.137625631329235 -0.15756248166201 -0.0123743686707645"
      rpy="1.5707963267949 -1.50975652463866 0" />
    <parent
      link="base_link" />
    <child
      link="back_right_wheel" />
    <axis
      xyz="0 0 1" />
  </joint>

<xacro:wheel_property prefix = "back" suffix ="left"/>
<xacro:wheel_property prefix = "back" suffix ="right"/>
<xacro:wheel_property prefix = "front" suffix ="left"/>
<xacro:wheel_property prefix = "front" suffix ="right"/>

  <link
    name="lidar_link">
    <inertial>
      <origin
        xyz="4.09116172421151E-06 0.0931474214750009 0.0291271902028432"
        rpy="0 0 0" />
      <mass
        value="${lidar_mass}" />
      <inertia
        ixx="0.0179107890685936"
        ixy="2.18506789618935E-06"
        ixz="3.01163371410289E-06"
        iyy="0.0133315302435088"
        iyz="1.8715661867103E-05"
        izz="0.0174435923665994" />
    </inertial>
    <visual>
      <origin
        xyz="0 0 0"
        rpy="0 0 0" />
      <geometry>
        <mesh
          filename="package://four_wheel_urdf/meshes/lidar_link.STL" />
      </geometry>
      <material
        name="">
        <color
          rgba="1 1 1 1" />
      </material>
    </visual>
    <!--
    <collision>
      <origin
        xyz="0 0 0"
        rpy="0 0 0" />
      <geometry>
        <mesh
          filename="package://four_wheel_urdf/meshes/lidar_link.STL" />
      </geometry>
    </collision>
    -->
  </link>
  <joint
    name="lidar_joint"
    type="fixed">
    <origin
      xyz="0.10636719253573 0 0.084"
      rpy="1.5707963267949 0 1.5707963267949" />
    <parent
      link="base_link" />
    <child
      link="lidar_link" />
    <axis
      xyz="0 0 0" />
  </joint>
  <link
    name="kinect_link">
    <inertial>
      <origin
        xyz="4.53003150256461E-05 -0.0022512727589919 -0.0310890480711258"
        rpy="0 0 0" />
      <mass
        value="${kinect_mass}" />
      <inertia
        ixx="0.000269628323265001"
        ixy="-9.35635942556109E-07"
        ixz="4.36911806541317E-08"
        iyy="0.00298637400697551"
        iyz="5.71455101111892E-06"
        izz="0.00311135598247432" />
    </inertial>
    <visual>
      <origin
        xyz="0 0 0"
        rpy="0 0 0" />
      <geometry>
        <mesh
          filename="package://four_wheel_urdf/meshes/kinect_link.STL" />
      </geometry>
      <material
        name="">
        <color
          rgba="0.494117647058824 0.494117647058824 0.494117647058824 1" />
      </material>
    </visual>
    <!--
    <collision>
      <origin
        xyz="0 0 0"
        rpy="0 0 0" />
      <geometry>
        <mesh
          filename="package://four_wheel_urdf/meshes/kinect_link.STL" />
      </geometry>
    </collision>
    -->
  </link>
  <joint
    name="kinect_joint"
    type="fixed">
    <origin
      xyz="0.15 0 0.31"
      rpy="3.14159265358979 0 1.5707963267949" />
    <parent
      link="base_link" />
    <child
      link="kinect_link" />
    <axis
      xyz="0 0 0" />
  </joint>
  <link
    name="raspberry_link">
    <inertial>
      <origin
        xyz="0.000461726517500066 5.2625477320288E-05 0.0180385455431908"
        rpy="0 0 0" />
      <mass
        value="0.176384011821692" />
      <inertia
        ixx="6.51045221494184E-05"
        ixy="3.16323813848326E-07"
        ixz="-1.7003346795475E-07"
        iyy="0.000126949390234811"
        iyz="-9.47083683760902E-08"
        izz="0.000154309006147346" />
    </inertial>
    <visual>
      <origin
        xyz="0 0 0"
        rpy="0 0 0" />
      <geometry>
        <mesh
          filename="package://four_wheel_urdf/meshes/raspberry_link.STL" />
      </geometry>
      <material
        name="">
        <color
          rgba="1 1 1 1" />
      </material>
    </visual>
    <!--
    <collision>
      <origin
        xyz="0 0 0"
        rpy="0 0 0" />
      <geometry>
        <mesh
          filename="package://four_wheel_urdf/meshes/raspberry_link.STL" />
      </geometry>
    </collision>
    -->
  </link>
  <joint
    name="raspberry_joint"
    type="fixed">
    <origin
      xyz="-0.0394022599786004 -0.0789158736827855 0.038"
      rpy="3.14159265358979 0 1.5707963267949" />
    <parent
      link="base_link" />
    <child
      link="raspberry_link" />
    <axis
      xyz="0 0 0" />
  </joint>
  <link
    name="driver_link">
    <inertial>
      <origin
        xyz="-0.0187299099866179 0.0128318998345537 -0.00696970391864018"
        rpy="0 0 0" />
      <mass
        value="0.0275146541367252" />
      <inertia
        ixx="3.2123731049697E-06"
        ixy="-3.79930759145132E-08"
        ixz="4.57665322377566E-09"
        iyy="6.00635714688659E-06"
        iyz="2.60757429384177E-10"
        izz="8.95655823044556E-06" />
    </inertial>
    <visual>
      <origin
        xyz="0 0 0"
        rpy="0 0 0" />
      <geometry>
        <mesh
          filename="package://four_wheel_urdf/meshes/driver_link.STL" />
      </geometry>
      <material
        name="">
        <color
          rgba="0.792156862745098 0.819607843137255 0.933333333333333 1" />
      </material>
    </visual>
    <!--
    <collision>
      <origin
        xyz="0 0 0"
        rpy="0 0 0" />
      <geometry>
        <mesh
          filename="package://four_wheel_urdf/meshes/driver_link.STL" />
      </geometry>
    </collision>
    -->
  </link>
  <joint
    name="driver_joint"
    type="fixed">
    <origin
      xyz="-0.0214789929081909 0.0579006571709648 0.0296921128243262"
      rpy="0 0 1.5707963267949" />
    <parent
      link="base_link" />
    <child
      link="driver_link" />
    <axis
      xyz="0 0 0" />
  </joint>

  <!-- Gazebo plugin for ROS Control -->
  <gazebo>
    <plugin name="gazebo_ros_control" filename="libgazebo_ros_control.so">
      <robotNamespace>/</robotNamespace>
    </plugin>
  </gazebo>
</robot>
